Workbook
Name DataIVA: #REF!
Name RangoNombre2: R_CLIENTES!$A:$A
Name RegiPeri: #REF!
Name RangoNombre1: R_CLIENTES!$1:$1000
Name ListPeri: #REF!
Name R_CLIENTES: R_CLIENTES!$1:$1000
Name DataBanc: #REF!
Name DataVend: #REF!

Sheet Modelo Cotización
G2: Nro de Cotización:
G3: 82
D9: Sucursales: Marco Gallo Vergara 536 B, Dpto 411 Torre D | AE9: =G3 -> 82
D10: Casa Matriz: Huerfanos, 1055 Oficina 503
D11: Giro: Servicios de Seguridad y Cerrajería
D12: eMail: ventas@polygonos.cl
D13: Fono: 9-81334980 | AD13: ="Fecha de Cotización: " & TEXT(IFERROR(VLOOKUP($AE$9, R_COTIZACIONES!$A$6:$B1000, 2, FALSE), ""), "dd-mm-yyyy") -> Fecha de Cotización: 04-03-2026
D14: Vendedor: Maximo Hudson / maximo.hudson.blanco@gmail.com
D16: Nombre Cliente: | L16: =IFERROR(VLOOKUP($AE$9, R_COTIZACIONES!$A$6:$G1000, 5, FALSE), "Sin contacto") -> Diego Palma
D17: R.U.T.: | G17: =IFERROR(VLOOKUP($AE$9, R_COTIZACIONES!$A:$C, 3, FALSE), "") -> 65.066.845-6
D18: Razon Social: | K18: =IFERROR(VLOOKUP($AE$9, R_COTIZACIONES!$A:$E, 4, FALSE), "No encontrado") -> Condominio Ossandon
D19: Dirección: | I19: =IFERROR(VLOOKUP(VLOOKUP($AE$9, R_COTIZACIONES!$A$6:$C1000, 3, FALSE), R_CLIENTES!$A$3:$C1000, 3, FALSE), "Dirección no encontrada") -> Av Ossandón 60
D20: Comuna: | I20: =IFERROR(VLOOKUP(VLOOKUP($AE$9, R_COTIZACIONES!$A$6:$C1000, 3, FALSE), R_CLIENTES!$A$3:$D1000, 4, FALSE), "") -> Coquimbo | S20: Telefono: | W20: {=IFERROR(VLOOKUP(TRIM($AE$9), TRIM(R_COTIZACIONES!$A:$G), 7, FALSE), "No encontrado")} -> 9 9969 8228
D21: Correo: | H21: =IFERROR(VLOOKUP(VLOOKUP($AE$9, R_COTIZACIONES!$A$6:$C1000, 3, FALSE), R_CLIENTES!$A$3:$I1000, 9, FALSE), "Correo no registrado") -> admossandon@gmail.com
D23: Código | I23: Descripción | AB23: Cantidad | AG23: Valor Uni | AM23: % Desc. | AQ23: Sub Total
A24: 1 | B24: =CONCATENATE($AE$9,"a",A24) -> 82a1 | D24: =IFERROR(__xludf.DUMMYFUNCTION("IFERROR(FILTER('Detalle Cotización'!H:H, 'Detalle Cotización'!B:B = $AE$9), """")"),"S18") -> S18 | I24: =IFERROR(__xludf.DUMMYFUNCTION("IFERROR(FILTER('Detalle Cotización'!I:I, 'Detalle Cotización'!B:B = $AE$9), """")"),"Servicio CCTV e Infraestrcutura para exteriores y 2 cámaras en poste.") -> Servicio CCTV e Infraestrcutura para exteriores y 2 cámaras en poste. | AD24: =IFERROR(__xludf.DUMMYFUNCTION("IFERROR(FILTER('Detalle Cotización'!J4:J1000, 'Detalle Cotización'!B4:B1000 = $AE$9), """")"),1.0) -> 1 | AG24: =IFERROR(__xludf.DUMMYFUNCTION("IFERROR(FILTER('Detalle Cotización'!K:K, 'Detalle Cotización'!B:B = $AE$9), """")"),3640000.0) -> 3640000 | AM24: =IFERROR(__xludf.DUMMYFUNCTION("IFERROR(FILTER('Detalle Cotización'!L4:L1000, 'Detalle Cotización'!B4:B1000 = $AE$9), """")"),0.0) -> 0 | AQ24: =IFERROR(__xludf.DUMMYFUNCTION("IFERROR(FILTER('Detalle Cotización'!M4:M1000, 'Detalle Cotización'!B4:B1000 = $AE$9), """")"),3640000.0) -> 3640000
A25: 2 | B25: =CONCATENATE($AE$9,"a",A25) -> 82a2
A26: 3 | B26: =CONCATENATE($AE$9,"a",A26) -> 82a3
A27: 4 | B27: =CONCATENATE($AE$9,"a",A27) -> 82a4
A28: 5 | B28: =CONCATENATE($AE$9,"a",A28) -> 82a5
A29: 6 | B29: =CONCATENATE($AE$9,"a",A29) -> 82a6
A30: 7 | B30: =CONCATENATE($AE$9,"a",A30) -> 82a7
A31: 8 | B31: =CONCATENATE($AE$9,"a",A31) -> 82a8
A32: 9 | B32: =CONCATENATE($AE$9,"a",A32) -> 82a9
A33: 10 | B33: =CONCATENATE($AE$9,"a",A33) -> 82a10
A34: 11 | B34: =CONCATENATE($AE$9,"a",A34) -> 82a11
A35: 12 | B35: =CONCATENATE($AE$9,"a",A35) -> 82a12
A36: 13 | B36: =CONCATENATE($AE$9,"a",A36) -> 82a13
... A38: 15 | B38: =CONCATENATE($AE$9,"a",A38) -> 82a15
D40: Comentarios: | AL40: Total Neto | AM40: =SUM(AQ24:AV38) -> 3640000
D41: =IFERROR(VLOOKUP($AE$9, R_COTIZACIONES!$A$4:$Q1000, 14, FALSE), "") -> Valor CCTV cámaras exteriores (2) e infraestructura base CCTV IP.
AL42: Total | AM42: =SUM(AM40:AP41) -> 3640000
D45: Forma de Pago:
D46: =IFERROR(VLOOKUP($AE$9, R_COTIZACIONES!$A$4:$Q1000, 9, FALSE), "") -> 50 anticipo y 50 al finalizar
D49: Terminos y Condiciones:
D50: 1-. El trabajo de ejecuta posterior a la aceptación de la cotización y coordinación de fecha de instalación y entrega.
D51: 2-. No refiere stock ni fecha de instalación.
D52: 3-. Cotización válida por 15 días.
D54: Pagos en transferencia, efectivo o cheque a nombre de:
D56: ='Base de datos'!C3 -> Polygonos SPA RUT: 77.180.437-3 Banco Santander Cta. Cte. 99128755 Correo: maximo.hudson.blanco@gmail.com
...

Sheet Base de datos
A2: Aplicar IVA | B2: Vendedor | C2: Datos Bancarios
A3: Si | B3: Maximo Hudson | C3: Polygonos SPA RUT: 77.180.437-3 Banco Santander Cta. Cte. 99128755 Correo: maximo.hudson.blanco@gmail.com | F3: Costos CCTV (Proveedores)
A4: no | B4: Maximo Hudson | C4: Maximo Hudson 26074100-4 Banco Santander Cta. Cte.: 75 36164 5 Correo: maximo.hudson.blanco@gmail.com | E4: Cod | F4: Producto | G4: Modelo | H4: Proveedor | I4: Link publicado | J4: Valor publicado | K4: Neto | L4: IVA | M4: Margen | N4: Precio Venta | O4: Cant | P4: Total | Q4: Utilidad
E5: N32 | F5: NVR | G5: NVR4232-4KS3 | H5: Smart Secure | I5: Link | J5: 190324 | K5: =J5/1.19 -> 159936.13 | L5: =J5-K5 -> 30387.866 | M5: =J5*0.6 -> 114194.4 | N5: =J5+M5 -> 304518.4 | O5: 1 | P5: =N5 -> 304518.4 | Q5: =P5/1.6 -> 190324
A6: Periodo | E6: N32-E | F6: NVR | G6: NVR4232-4KS3 | H6: IAI Tech | I6: Link | J6: 182000 | K6: =J6/1.19 -> 152941.18 | L6: =J6-K6 -> 29058.824 | M6: =J6*0.6 -> 109200 | N6: =J6+M6 -> 291200 | O6: 1 | P6: =N6 -> 291200 | Q6: =P6/1.6 -> 182000
A7: Hoy | B7: =TODAY() -> 46088 | C7: =TODAY() -> 46088 | E7: H4TB | F7: HDD 4 TB | G7: ST4000VX015 | H7: Smart Secure | I7: Link | J7: 135096 | K7: =J7/1.19 -> 113526.05 | L7: =J7-K7 -> 21569.95 | M7: =J7*0.6 -> 81057.6 | N7: =J7+M7 -> 216153.6 | O7: 2 | P7: =N7*O7 -> 432307.2 | Q7: =P7/1.6 -> 270192
A8: Enero | B8: 45658 | C8: 45688 | E8: H6TB | F8: HDD 6 TB | G8: WD60EFFX | H8: IAI Tech | I8: Link | J8: 219990 | K8: =J8/1.19 -> 184865.55 | L8: =J8-K8 -> 35124.454 | M8: =J8*0.6 -> 131994 | N8: =J8+M8 -> 351984 | O8: 1 | P8: =N8*O8 -> 351984 | Q8: =P8/1.6 -> 219990
A9: Febrero | B9: 45689 | C9: 45716 | E9: UPS15 | F9: UPS 1500 VA | G9: DH-PFM350-900-A | H9: Smart Secure | I9: Link | J9: 84238 | K9: =J9/1.19 -> 70788.235 | L9: =J9-K9 -> 13449.765 | M9: =J9*0.6 -> 50542.8 | N9: =J9+M9 -> 134780.8 | O9: 2 | P9: =N9*O9 -> 269561.6 | Q9: =P9/1.6 -> 168476
A10: Marzo | B10: 45717 | C10: 45747 | E10: UPS15 | F10: UPS 1500 VA | G10: MR-UF1500 | H10: IAI Tech | I10: Link | J10: 116991 | K10: =J10/1.19 -> 98311.765 | L10: =J10-K10 -> 18679.235 | M10: =J10*0.6 -> 70194.6 | N10: =J10+M10 -> 187185.6 | O10: 2 | P10: =N10*O10 -> 374371.2 | Q10: =P10/1.6 -> 233982
A11: Abril | B11: 45748 | C11: 45777 | E11: SW24 | F11: Switch 24 | G11: DH-CS4228-24GT-240 | H11: IAI Tech | I11: Link | J11: 349550 | K11: =J11/1.19 -> 293739.5 | L11: =J11-K11 -> 55810.504 | M11: =J11*0.6 -> 209730 | N11: =J11+M11 -> 559280 | O11: 1 | P11: =N11*O11 -> 559280 | Q11: =P11/1.6 -> 349550
A12: Mayo | B12: 45778 | C12: 45808 | E12: SW24 | F12: Switch 24 | G12: DH-CS4228-24GT-240 | H12: Smart Secure | I12: Link | J12: 240211 | K12: =J12/1.19 -> 201857.98 | L12: =J12-K12 -> 38353.017 | M12: =J12*0.6 -> 144126.6 | N12: =J12+M12 -> 384337.6 | O12: 1 | P12: =N12*O12 -> 384337.6 | Q12: =P12/1.6 -> 240211
A13: Junio | B13: 45809 | C13: 45838 | E13: SW8 | F13: Switch 8 | G13: DH-PFS3010-8ET-65 | H13: Smart Secure | I13: Link | J13: 63603 | K13: =J13/1.19 -> 53447.899 | L13: =J13-K13 -> 10155.101 | M13: =J13*0.6 -> 38161.8 | N13: =J13+M13 -> 101764.8 | O13: 2 | P13: =N13*O13 -> 203529.6 | Q13: =P13/1.6 -> 127206
A14: Julio | B14: 45839 | C14: 45869 | E14: SW8 | F14: Switch 8 | G14: POE208-100MB | H14: IAI Tech | I14: Link | J14: 36400 | K14: =J14/1.19 -> 30588.235 | L14: =J14-K14 -> 5811.7647 | M14: =J14*0.6 -> 21840 | N14: =J14+M14 -> 58240 | O14: 2 | P14: =N14*O14 -> 116480 | Q14: =P14/1.6 -> 72800
A15: Agosto | B15: 45870 | C15: 45900 | E15: SW4 | F15: Switch 4 | G15: DH-PFS3006-4ET-36 | H15: Smart Secure | I15: Link | J15: 35079 | K15: =J15/1.19 -> 29478.151 | L15: =J15-K15 -> 5600.8487 | M15: =J15*0.6 -> 21047.4 | N15: =J15+M15 -> 56126.4 | O15: 3 | P15: =N15*O15 -> 168379.2 | Q15: =P15/1.6 -> 105237
A16: Septiembre | B16: 45901 | C16: 45930 | E16: SW4 | F16: Switch 4 | G16: POE204-100MB | H16: IAI Tech | I16: Link | J16: 23600 | K16: =J16/1.19 -> 19831.933 | L16: =J16-K16 -> 3768.0672 | M16: =J16*0.6 -> 14160 | N16: =J16+M16 -> 37760 | O16: 3 | P16: =N16*O16 -> 113280 | Q16: =P16/1.6 -> 70800
A17: Octubre | B17: 45931 | C17: 45961 | E17: RC20 | F17: Router Inalambrico | G17: Archer C20 | H17: Smart Secure | I17: Link | J17: 25368 | K17: =J17/1.19 -> 21317.647 | L17: =J17-K17 -> 4050.3529 | M17: =J17*0.6 -> 15220.8 | N17: =J17+M17 -> 40588.8 | O17: 1 | P17: =N17*O17 -> 40588.8 | Q17: =P17/1.6 -> 25368
A18: Noviembre | B18: 45962 | C18: 45991 | E18: RC21 | F18: Router Inalambrico | G18: RG-EW1200G PRO | H18: IAI Tech | I18: Link | J18: 41500 | K18: =J18/1.19 -> 34873.95 | L18: =J18-K18 -> 6626.0504 | M18: =J18*0.6 -> 24900 | N18: =J18+M18 -> 66400 | O18: 1 | P18: =N18*O18 -> 66400 | Q18: =P18/1.6 -> 41500
A19: Diciembre | B19: 45992 | C19: 46022 | E19: UBIM5 | F19: Antenas | G19: Loco M5 (par) | H19: Clickbox | I19: Link | J19: 155990 | K19: =J19/1.19 -> 131084.03 | L19: =J19-K19 -> 24905.966 | M19: =J19*0.6 -> 93594 | N19: =J19+M19 -> 249584 | O19: 4 | P19: =N19*O19 -> 998336 | Q19: =P19/1.6 -> 623960
E20: CPE51 | F20: Antenas | G20: WI-CPE511H-KIT | H20: ANTENASCHILE | I20: Link | J20: 119990 | K20: =J20/1.19 -> 100831.93 | L20: =J20-K20 -> 19158.067 | M20: =J20*0.6 -> 71994 | N20: =J20+M20 -> 191984 | O20: 4 | P20: =N20*O20 -> 767936 | Q20: =P20/1.6 -> 479960
A21: 2024 | E21: 1230T1 | F21: Camara Domo | G21: DH-IPC-HDW1230T1-0280B | H21: Smart Secure | I21: Link | J21: 44061 | K21: =J21/1.19 -> 37026.05 | L21: =J21-K21 -> 7034.9496 | M21: =J21*0.6 -> 26436.6 | N21: =J21+M21 -> 70497.6 | O21: 18 | P21: =N21*O21 -> 1268956.8 | Q21: =P21/1.6 -> 793098
A22: Enero | B22: 45292 | C22: 45322 | E22: 1430T1 | F22: Camara Domo | G22: DH-IPC-HDW1431T1P-A-0280B-S6 | H22: IAI Tech | I22: Link | J22: 52191 | K22: =J22/1.19 -> 43857.983 | L22: =J22-K22 -> 8333.0168 | M22: =J22*0.6 -> 31314.6 | N22: =J22+M22 -> 83505.6 | O22: 18 | P22: =N22*O22 -> 1503100.8 | Q22: =P22/1.6 -> 939438
A23: Febrero | B23: 45323 | C23: 45350 | E23: 1239S1 | F23: Cámara Bullet | G23: DH-IPC-HFW1239S1-LED-0280B | H23: Smart Secure | I23: Link | J23: 43940 | K23: =J23/1.19 -> 36924.37 | L23: =J23-K23 -> 7015.6303 | M23: =J23*0.6 -> 26364 | N23: =J23+M23 -> 70304 | O23: 12 | P23: =N23*O23 -> 843648 | Q23: =P23/1.4 -> 602605.71
A24: Marzo | B24: 45352 | C24: 45382 | E24: 2249S | F24: Cámara Bullet | G24: DH-IPC-HFW2249S-S-IL | H24: IAI Tech | I24: Link | J24: 66591 | K24: =J24/1.19 -> 55958.824 | L24: =J24-K24 -> 10632.176 | M24: =J24*0.4 -> 26636.4 | N24: =J24+M24 -> 93227.4 | O24: 12 | P24: =N24*O24 -> 1118728.8 | Q24: =P24/1.4 -> 799092
A25: Abril | B25: 45383 | C25: 45412 | E25: 304020 | F25: Gabinete exteriores | G25: Gabinete Mural-304020 | H25: IAI Tech | I25: Link | J25: 37990 | K25: =J25/1.19 -> 31924.37 | L25: =J25-K25 -> 6065.6303 | M25: =J25*0.6 -> 22794 | N25: =J25+M25 -> 60784 | O25: 4 | P25: =N25*O25 -> 243136 | Q25: =P25/1.6 -> 151960
A26: Mayo | B26: 45413 | C26: 45443 | E26: 604550 | F26: Rack Gabinete interior | G26: Gabinete Rack 6U Dahua 600x450x501 | H26: Smart Secure | I26: Link | J26: 94070 | K26: =J26/1.19 -> 79050.42 | L26: =J26-K26 -> 15019.58 | M26: =J26*0.6 -> 56442 | N26: =J26+M26 -> 150512 | O26: 1 | P26: =N26*O26 -> 150512 | Q26: =P26/1.6 -> 94070
A27: Junio | B27: 45444 | C27: 45473 | E27: 534020 | F27: Rack Gabinete interior | G27: Gabinete Rack 4U Dahua 530X400X200 | H27: Smart Secure | I27: Link | J27: 60933 | K27: =J27/1.19 -> 51204.202 | L27: =J27-K27 -> 9728.7983 | M27: =J27*0.6 -> 36559.8 | N27: =J27+M27 -> 97492.8 | O27: 1 | P27: =N27*O27 -> 97492.8 | Q27: =P27/1.6 -> 60933
A28: Julio | B28: 45474 | C28: 45504 | E28: 534060 | F28: Rack Gabinete interior | G28: Gabinete Rack 12U Dahua 530x400x600 | H28: IAI Tech | I28: Link | J28: 102150 | K28: =J28/1.19 -> 85840.336 | L28: =J28-K28 -> 16309.664 | M28: =J28*0.6 -> 61290 | N28: =J28+M28 -> 163440 | O28: 1 | P28: =N28*O28 -> 163440 | Q28: =P28/1.6 -> 102150
A29: Agosto | B29: 45505 | C29: 45535 | E29: PATCH24 | F29: Patch panel | G29: Patch panel 24 puertos Cat 6 | H29: IAI Tech | I29: Link | J29: 15500 | K29: =J29/1.19 -> 13025.21 | L29: =J29-K29 -> 2474.7899 | M29: =J29*0.6 -> 9300 | N29: =J29+M29 -> 24800 | O29: 1 | P29: =N29*O29 -> 24800 | Q29: =P29/1.6 -> 15500
A30: Septiembre | B30: 45536 | C30: 45565 | E30: PATCH24 | F30: Patch panel | G30: Patch panel 24 puertos Cat 6 | H30: Clickbox | I30: Link | J30: 36295 | K30: =J30/1.19 -> 30500 | L30: =J30-K30 -> 5795 | M30: =J30*0.6 -> 21777 | N30: =J30+M30 -> 58072 | O30: 1 | P30: =N30*O30 -> 58072 | Q30: =P30/1.6 -> 36295
A31: Octubre | B31: 45566 | C31: 45596 | E31: PATCH972 | F31: Patch cord | G31: DH-PFM972-6U-2-S | H31: Smart Secure | I31: Link | J31: 2306 | K31: =J31/1.19 -> 1937.8151 | L31: =J31-K31 -> 368.18487 | M31: =J31*0.6 -> 1383.6 | N31: =J31+M31 -> 3689.6 | O31: 30 | P31: =N31*O31 -> 110688 | Q31: =P31/1.6 -> 69180
A32: Noviembre | B32: 45597 | C32: 45626 | E32: CAT6305 | F32: Caja de cable Cat 6 305 | G32: DH-PFM923I-6UN-C | H32: Smart Secure | I32: Link | J32: 135581 | K32: =J32/1.19 -> 113933.61 | L32: =J32-K32 -> 21647.387 | M32: =J32*0.6 -> 81348.6 | N32: =J32+M32 -> 216929.6 | O32: 4 | P32: =N32*O32 -> 867718.4 | Q32: =P32/1.6 -> 542324
A33: Diciembre | B33: 45627 | C33: 45657 | E33: CAT6100 | F33: Caja de cable Cat 6 100 | G33: DH-PFM920I-6UN-C-100 | H33: Smart Secure | I33: Link | J33: 47824 | K33: =J33/1.19 -> 40188.235 | L33: =J33-K33 -> 7635.7647 | M33: =J33*0.6 -> 28694.4 | N33: =J33+M33 -> 76518.4 | O33: 2 | P33: =N33*O33 -> 153036.8 | Q33: =P33/1.6 -> 95648
E34: CAN10050 | F34: Canaletas troncal 100x50 | G34: CANAL100X50 | H34: Moreto clima | I34: Link | J34: 7965 | K34: =J34/1.19 -> 6693.2773 | L34: =J34-K34 -> 1271.7227 | M34: =J34*0.6 -> 4779 | N34: =J34+M34 -> 12744 | O34: 20 | P34: =N34*O34 -> 254880 | Q34: =P34/1.6 -> 159300
A35: Forma de pago | B35: Estado | E35: CAE100100 | F35: Caja estanca 100x100 | G35: Cono 10010070 | H35: IAI Tech | I35: Link | J35: 2450 | K35: =J35/1.19 -> 2058.8235 | L35: =J35-K35 -> 391.17647 | M35: =J35*0.6 -> 1470 | N35: =J35+M35 -> 3920 | O35: 30 | P35: =N35*O35 -> 117600 | Q35: =P35/1.6 -> 73500
A36: Contado | B36: Aprobado
A37: 50 anticipo y 50 al finalizar | B37: Pendiente | F37: Costos Motores y Accesorios (Proveedores)
A38: 0 a 30 días | B38: Rechazado | E38: Cod | F38: Categoría | G38: Modelo | H38: Proveedor | I38: Link publicado | J38: Valor publicado | K38: Neto | L38: IVA | M38: Margen | N38: Precio Venta | O38: Cant | P38: Total | Q38: Utilidad
A39: Al finalizar | E39: D10S | F39: Motor Corredera | G39: D10 Standard | H39: RW | I39: N/A | J39: 639018 | K39: =J39/1.19 -> 536989.92 | L39: =J39-K39 -> 102028.08 | M39: =J39*0.6 -> 383410.8 | N39: =J39+M39 -> 1022428.8 | O39: 1 | P39: =N39 -> 1022428.8 | Q39: =P39/1.6 -> 639018
A40: 33% inicial 33% a 30 días y 33% a 60 días | K40: =J40/1.19 -> 0 | L40: =J40-K40 -> 0 | M40: =J40*0.6 -> 0 | N40: =J40+M40 -> 0 | P40: =N40 -> 0 | Q40: =P40/1.6 -> 0
E41: D10S | F41: Motor Corredera | G41: D10 Standard | H41: APACOM | I41: N/A | J41: 640208 | K41: =J41/1.19 -> 537989.92 | L41: =J41-K41 -> 102218.08 | M41: =J41*0.6 -> 384124.8 | N41: =J41+M41 -> 1024332.8 | O41: 1 | P41: =N41 -> 1024332.8 | Q41: =P41/1.6 -> 640208
...

Sheet R_CLIENTES
A1: RUT | B1: RAZÓN SOCIAL | C1: DIRECCION | D1: COMUNA | E1: CIUDAD | F1: REGIÓN | G1: CONTACTO | H1: TELÉFONO | I1: MAIL | J1: Columna 1 | K1: Columna 2 | L1: Columna 3 | M1: Columna 4 | N1: Columna 5 | O1: Columna 6 | P1: Columna 7 | Q1: Columna 8 | R1: Columna 9 | S1: Columna 10 | T1: Columna 11 | U1: Columna 12 | V1: Columna 13 | W1: Columna 14 | X1: Columna 15 | Y1: Columna 16 | Z1: Columna 17
A2: 53320939-4 | B2: Condominio Paseo Peñuelas | C2: AV. PACIFICO 5208 | D2: La Serena | E2: La Serena | F2: Coquimbo | G2: Adm Victor Figueroa | H2: 9-59823214 | I2: Pendiente correo
A3: 53334332-5 | B3: Condominio Mirador Los Clarines | C3: Av Los Clarines 1575 | D3: Coquimbo | E3: Coquimbo | F3: Coquimbo | G3: Emerson Castillo | H3: 9-5982-3214 | I3: condominiomiradordelosclarines@gmail.com
A4: 65198585-4 | B4: Condominio Vicenza II | C4: Av. Marco Gallo Vergara 536 | D4: La Serena | E4: La Serena | F4: Coquimbo | G4: Mauricio Araya | H4: 9-97269955 | I4: mauricio@mypspa.cl
A5: 53333086-k | B5: Condominio Colinas del Milagro | C5: Enrique Lynch 4332 | D5: La Serena | E5: La Serena | F5: Coquimbo | G5: Mauricio Araya | H5: 9-97269955 | I5: mauricio@mypspa.cl
A6: 76733113-4 | B6: RW SPA | C6: Arzobispo Larrain Gandarillas 87 | D6: Providencia | E6: Santiago | F6: Santiago | G6: Leonardo Arriaga | H6: SIN TELEFONO | I6: -
A7: 65216508-7 | B7: Condominio Mirador El Milagro | C7: Av. Las Palmeras 7000 | D7: La Serena | E7: La Serena | F7: Coquimbo | G7: Camila Godoy | H7: 9-44637185 | I7: condominiomiradorelmilagro@gmail.com
A8: 76470822-9 | B8: Sociedad Educacional Shalom SpA | C8: Avda. El Rosario 3870 | D8: Coquimbo | E8: Coquimbo | F8: Coquimbo | G8: Jorge Adm | H8: 999847687 | I8: contacto@amazinggraceco.cl
A9: 65203446-2 | B9: Condominio Altos del Parque | C9: G. Mistral 3605 E-1 Altos del Pque | D9: La Serena | E9: La Serena | F9: Coquimbo | G9: Maria Antoniera del Pino | H9: 9-84398698 | I9: -
A10: 50.000.001-0 | B10: Condominio Lomas de San Joaquin | C10: Av Gabriela Mistral 3670 | D10: La Serena | E10: La Serena | F10: Coquimbo | G10: Paola Robles | H10: 9-95802922 | I10: -
A11: 56047780-5 | B11: Comunidad Edificio Florencia | C11: Av Puertas del mar 347 | D11: La Serena | E11: La Serena | F11: Coquimbo | G11: Guillermo Negrete | H11: 9-93590543 | I11: -
A12: 53322672-8 | B12: CONDOMINIO V.I.V.E LA FLORIDA ORIENTE | C12: Av El Litre 2162, La Florida | D12: La Serena | E12: La Serena | F12: Coquimbo | G12: Paola Robles | H12: 9-95802922 | I12: -
A13: 53.332.075-9 | B13: Condominio Jardin Central | C13: Blanco garces 154 | D13: Estacion Central | E13: Santiago | F13: Metropolitana | G13: Vanessa Guerra | H13: 9 49856345 | I13: administracion@jardincentro.cl
A14: 50.000.000-0 | B14: Edificio Puerta Centro | C14: Morande 857 | D14: Santiago Centro | E14: Santiago | F14: Metropolitana | G14: César | H14: 9 98402129 | I14: Epuertacentro@gmail.com
A15: 53.322.860-7 | B15: Condominio Los Tamarindos I | C15: Av Islón 1301 | D15: La Serena | E15: La Serena | F15: Coquimbo | G15: Norman Rojas | H15: 9 49856345 | I15: -
A16: 65.095.336-2 | B16: Condominio Neo Spazio | C16: Av Central 5000 | D16: Coquimbo | E16: La Serena | F16: Coquimbo | G16: Guillermo Negrete | H16: 9-93590543 | I16: condominioneospazio@gmail.com
A17: 76.324.502-0 | B17: CitoApp SpA | C17: Providencia 1650 oficina 1603 | D17: Providencia | E17: Santiago | F17: Metropolitana | G17: Rodrigo Mansilla | H17: 9 6699 9835 | I17: contacto@citoapp.cl
A18: 76.324.502- 0 | B18: Cond Artes 1 | C18: Av Alberto Carvajal 4235 | D18: La Serena | E18: La Serena | F18: Coquimbo | G18: Carlos Hinojosa | H18: 9 7806 9280
A19: 76.179.872-3 | B19: Sociedad Educacional Basaldiaz S.A | C19: Cruz del Molino #386 Puertas del Mar La Serena | D19: La Serena | E19: La Serena | F19: Coquimbo | G19: Jonatan Mena | H19: 949911870 | I19: adquisiciones@amazinggracels.cl
A20: 53332414-2 | B20: Portal del Valle II | C20: Calle Raul Bitran 3501 | D20: La Serena | E20: La Serena | F20: Coquimbo | G20: Mauricio Araya | H20: 9-97269955 | I20: mauricio@mypspa.cl
A21: 76256791-1 | B21: Condominio Verona | C21: Monaco 493 | D21: La Serena | E21: La Serena | F21: Coquimbo | G21: Guillermo Negrete | H21: 9-93590543
A22: 76866075-1 | B22: Paseo San Carlos VII | C22: Waldo alcalde 1180 | D22: Coquimbo | E22: Coquimbo | F22: Coquimbo | G22: Claudio García | H22: 9-84398698
A23: 65.229.898-2 | B23: Distrito Verde I | C23: Emilio Apey 405 | D23: La Serena | E23: La Serena | F23: Coquimbo | G23: Maria Antonieta del Pino | H23: 9-84398698 | I23: madelpinoarcos@gmail.com
A24: 65.244.656- 6 | B24: Distrito Verde II | C24: Emilio Apey 409 | D24: La Serena | E24: La Serena | F24: Coquimbo | G24: Maria Antonieta del Pino | H24: 9-84398698 | I24: madelpinoarcos@gmail.com
A25: 79866075-1 | B25: Cond Doña Anita | C25: Av del mar 3320 | D25: La Serena | E25: La Serena | F25: Coquimbo | G25: Noema Reyes | H25: 9 7731 14628
A26: 53332351-0 | B26: Cond Aires de La Florida 4 | C26: Los Arándonos 5506 | D26: La Serena | E26: La Serena | F26: Coquimbo | G26: Camila Godoy | H26: 9-7684 0230
A27: 90000000-1 | B27: Condominio Gabriela Mistral | C27: Av Libertadores | D27: La Serena | E27: La Serena | F27: Coquimbo | G27: Mauricio Araya | H27: 9-97269955 | I27: mauricio@mypspa.cl
A28: 90000002-1 | B28: Condominio Golf III | C28: Enrique Abbott 380 | D28: La Serena | E28: La Serena | F28: Coquimbo | G28: Oscar Castro | H28: 9 9450 8233
A29: 90000003-1 | B29: Juan Fernando Mancilla | C29: Enrique Abbott 390 | D29: La Serena | E29: La Serena | F29: Coquimbo | G29: Juan Fernando Mancilla | H29: 999680974 | I29: jperez@gmail.com
A30: 65242132-6 | B30: Condominio Alto Bellavista | C30: Av Las Palmeras 740 | D30: La Serena | E30: La Serena | F30: Coquimbo | G30: Maria Antoniera del Pino | H30: 9-84398698 | I30: madelpinoarcos@gmail.com
A31: 65106948-3 | B31: Condominio Capri | C31: Av Puertas del mar 425 | D31: La Serena | E31: La Serena | F31: Coquimbo | G31: Bernardita Orellana | H31: 9-93193675 | I31: adm.condominiocapri@gmail.com
A32: 76785900-7 | B32: Espacio Norte La Serena | C32: El Rodillo Parcela 125 Vegas Norte La Serena | D32: La Serena | E32: La Serena | F32: Coquimbo | G32: Juan Retamal | H32: 9-985690424 | I32: contacto@espacioserenanorte.cl
A33: 53318313-1 | B33: Condominio Parque Libertad | C33: Juan Lorenzo Solis Castro 520 | D33: La Serena | E33: La Serena | F33: Coquimbo | G33: Wilson Vargas | H33: 9-61183960 | I33: admparquelibertad@gmail.com
A34: 65094027-K | B34: Cond Marina Horizonte | C34: Av Los Pescadores 5301 | D34: Coquimbo | E34: Coquimbo | F34: Coquimbo | G34: Rodrigo Mancilla | H34: 9-6699 9835 | I34: rodrigomancilla@gmail.com
A35: 76866075-2 | B35: Condominio Pacífico | C35: Av Pacífico 3100 | D35: La Serena | E35: La Serena | F35: Coquimbo | G35: Gabriel Mollano | H35: 9-95906289
A36: 53.312.705-3 | B36: Condominio Palermo | C36: Av Roberto Flores 0175 | D36: La Serena | E36: La Serena | F36: Coquimbo | G36: Elvis Díaz | H36: 9-39074968 | I36: elvisdiazdiaz.adm@gmail.com
A37: 65.049.582-9 | B37: Espacio Urbano | C37: Av Francisco de Aguirre 075 | D37: La Serena | E37: La Serena | F37: Coquimbo | G37: Gypsy Adm | H37: 9 6287 8932 | I37: N/A
A38: 65.066.845-6 | B38: Condominio Ossandon | C38: Av Ossandón 60 | D38: Coquimbo | E38: Coquimbo | F38: Coquimbo | G38: Diego Palma | H38: 9 9969 8228 | I38: admossandon@gmail.com
A39: 65.110.744-K | B39: Condominio Bahia Horizonte | C39: Darío Salas 1111 | D39: Coquimbo | E39: Coquimbo | F39: Coquimbo | G39: Diego Palma | H39: 9 9969 8228 | I39: Cbh.adm.2025@gmail.com
A40: 53.330.222-K | B40: Condominio Jardines del Pacífico | C40: Av Pacifico 510 | D40: La Serena | E40: La Serena | F40: Coquimbo | G40: Sergio Cortez | H40: 9 5148 2432 | I40: condominiojardinesdelpacifico@gmail.com

Sheet R_COTIZACIONES
A3: ID_COT | B3: FECHA | C3: RUT_CLIENTE | D3: RAZÓN SOCIAL | E3: CONTACTO | F3: APLICA IVA | G3: TELEFÓNO | H3: VENDEDOR | I3: FORMA DE PAGO | J3: VALOR NETO | K3: IVA | L3: TOTAL | M3: DESCRIPCIÓN | N3: COMENTARIOS | O3: ESTADO | P3: DOCUMENTO | Q3: NRO DOCUMENTO | R3: Columna 7 | S3: Columna 8 | T3: Columna 9 | U3: Columna 10 | V3: Columna 11 | W3: Columna 12 | X3: Columna 13 | Y3: Columna 14 | Z3: Columna 15 | AA3: Columna 16
A4: 1 | B4: 45568 | C4: 53334332-5 | D4: {=IFERROR( INDEX(R_CLIENTES!B:B, MATCH(C4, R_CLIENTES!A:A, 0) ), "" )} -> Condominio Mirador Los Clarines | E4: {=IFERROR( INDEX(R_CLIENTES!G:G, MATCH(C4, R_CLIENTES!A:A, 0) ), "" )} -> Emerson Castillo | F4: Si | G4: {=IFERROR( INDEX(R_CLIENTES!H:H, MATCH(C4, R_CLIENTES!A:A, 0) ), "" )} -> 9-5982-3214 | H4: Maximo Hudson | I4: Al finalizar | J4: 200000 | K4: =IF(J4="","",IF(F4="SI",J4*0.19,0)) -> 38000 | L4: =IF(J4="","",J4+K4) -> 238000 | M4: Servicio de mantención Programada 2024 | O4: Aprobado
A5: 2 | B5: 45568 | C5: 53333086-k | D5: {=IFERROR( INDEX(R_CLIENTES!B:B, MATCH(C5, R_CLIENTES!A:A, 0) ), "" )} -> Condominio Colinas del Milagro | E5: {=IFERROR( INDEX(R_CLIENTES!G:G, MATCH(C5, R_CLIENTES!A:A, 0) ), "" )} -> Mauricio Araya | F5: Si | G5: {=IFERROR( INDEX(R_CLIENTES!H:H, MATCH(C5, R_CLIENTES!A:A, 0) ), "" )} -> 9-97269955 | H5: Maximo Hudson | I5: Al finalizar | J5: 200000 | K5: =IF(J5="","",IF(F5="SI",J5*0.19,0)) -> 38000 | L5: =IF(J5="","",J5+K5) -> 238000 | M5: Servicio de mantención Programada 2024 | O5: Aprobado
A6: 3 | B6: 45568 | C6: 56047780-5 | D6: {=IFERROR( INDEX(R_CLIENTES!B:B, MATCH(C6, R_CLIENTES!A:A, 0) ), "" )} -> Comunidad Edificio Florencia | E6: {=IFERROR( INDEX(R_CLIENTES!G:G, MATCH(C6, R_CLIENTES!A:A, 0) ), "" )} -> Guillermo Negrete | F6: Si | G6: {=IFERROR( INDEX(R_CLIENTES!H:H, MATCH(C6, R_CLIENTES!A:A, 0) ), "" )} -> 9-93590543 | H6: Maximo Hudson | I6: Al finalizar | J6: 220000 | K6: =IF(J6="","",IF(F6="SI",J6*0.19,0)) -> 41800 | L6: =IF(J6="","",J6+K6) -> 261800 | M6: Dispositivo GATOR para activación de portón remoto para apertura con aplicativo Protegus | N6: Dispositivo GATOR para activación de portón remoto para apertura con aplicativo Protegus (hasta 500 usuarios). | O6: Aprobado
A7: 4 | B7: 45568 | C7: 53322672-8 | D7: {=IFERROR( INDEX(R_CLIENTES!B:B, MATCH(C7, R_CLIENTES!A:A, 0) ), "" )} -> CONDOMINIO V.I.V.E LA FLORIDA ORIENTE | E7: {=IFERROR( INDEX(R_CLIENTES!G:G, MATCH(C7, R_CLIENTES!A:A, 0) ), "" )} -> Paola Robles | F7: Si | G7: {=IFERROR( INDEX(R_CLIENTES!H:H, MATCH(C7, R_CLIENTES!A:A, 0) ), "" )} -> 9-95802922 | H7: Maximo Hudson | I7: Al finalizar | J7: 300000 | K7: =IF(J7="","",IF(F7="SI",J7*0.19,0)) -> 57000 | L7: =IF(J7="","",J7+K7) -> 357000 | M7: Cambio Ruedas 24mm (par) | N7: Instalación de Rueda 100x100 doble rodamiento, cambio de las 2 ruedas pre existentes y una rueda entremedia 100x100 para redistribución de la carga total del portón. | O7: Rechazado
A8: 5 | B8: 45568 | C8: 50.000.001-0 | D8: {=IFERROR( INDEX(R_CLIENTES!B:B, MATCH(C8, R_CLIENTES!A:A, 0) ), "" )} -> Condominio Lomas de San Joaquin | E8: {=IFERROR( INDEX(R_CLIENTES!G:G, MATCH(C8, R_CLIENTES!A:A, 0) ), "" )} -> Paola Robles | F8: Si | G8: {=IFERROR( INDEX(R_CLIENTES!H:H, MATCH(C8, R_CLIENTES!A:A, 0) ), "" )} -> 9-95802922 | H8: Maximo Hudson | I8: 0 a 30 días | J8: 1400000 | K8: =IF(J8="","",IF(F8="SI",J8*0.19,0)) -> 266000 | L8: =IF(J8="","",J8+K8) -> 1666000 | M8: Kit D10 Smart con 6mts Cremallera M, CR y Baliza | N8: Kit incluye: Placa metálica de montaje, 6 cremalleras metálicas, 2 baterías de 12V/7amp (24V) de respaldo, 1 Control Transmisor NOVA, 1 Baliza 24V y 1 par de Fotocelda Centurion Smart | O8: Rechazado
A9: 6 | B9: 45574 | C9: 56047780-5 | D9: {=IFERROR( INDEX(R_CLIENTES!B:B, MATCH(C9, R_CLIENTES!A:A, 0) ), "" )} -> Comunidad Edificio Florencia | E9: {=IFERROR( INDEX(R_CLIENTES!G:G, MATCH(C9, R_CLIENTES!A:A, 0) ), "" )} -> Guillermo Negrete | F9: Si | G9: {=IFERROR( INDEX(R_CLIENTES!H:H, MATCH(C9, R_CLIENTES!A:A, 0) ), "" )} -> 9-93590543 | H9: Maximo Hudson | I9: 50 anticipo y 50 al finalizar | J9: 230000 | K9: =IF(J9="","",IF(F9="SI",J9*0.19,0)) -> 43700 | L9: =IF(J9="","",J9+K9) -> 273700 | M9: Servicio Mantención | N9: Cambio de Guías + reparación riel + reparación topes | O9: Rechazado
A10: 7 | B10: 45576 | C10: 53.322.860-7 | D10: {=IFERROR( INDEX(R_CLIENTES!B:B, MATCH(C10, R_CLIENTES!A:A, 0) ), "" )} -> Condominio Los Tamarindos I | E10: {=IFERROR( INDEX(R_CLIENTES!G:G, MATCH(C10, R_CLIENTES!A:A, 0) ), "" )} -> Norman Rojas | F10: no | G10: {=IFERROR( INDEX(R_CLIENTES!H:H, MATCH(C10, R_CLIENTES!A:A, 0) ), "" )} -> 9 49856345 | H10: Maximo Hudson | I10: 0 a 30 días | J10: 1500000 | K10: =IF(J10="","",IF(F10="SI",J10*0.19,0)) -> 0 | L10: =IF(J10="","",J10+K10) -> 1500000 | M10: Kit D10 Smart con 6mts Cremallera M, CR, Baliza y fotocelda Smart | N10: Kit incluye: Placa metálica de montaje, 6 cremalleras metálicas, 2 baterías de 12V/7amp (24V) de respaldo, 1 Control Transmisor NOVA, 1 Baliza 24V y 1 par de Fotocelda Centurion Smart | O10: Rechazado
A11: 8 | B11: 45576 | C11: 53.322.860-7 | D11: {=IFERROR( INDEX(R_CLIENTES!B:B, MATCH(C11, R_CLIENTES!A:A, 0) ), "" )} -> Condominio Los Tamarindos I | E11: {=IFERROR( INDEX(R_CLIENTES!G:G, MATCH(C11, R_CLIENTES!A:A, 0) ), "" )} -> Norman Rojas | F11: no | G11: {=IFERROR( INDEX(R_CLIENTES!H:H, MATCH(C11, R_CLIENTES!A:A, 0) ), "" )} -> 9 49856345 | H11: Maximo Hudson | I11: 50 anticipo y 50 al finalizar | J11: 220000 | K11: =IF(J11="","",IF(F11="SI",J11*0.19,0)) -> 0 | L11: =IF(J11="","",J11+K11) -> 220000 | M11: Dispositivo GATOR para activación de portón remoto para apertura con aplicativo Protegus | N11: Sistema para apertura remota mediante aplicativo protegus 2 | O11: Rechazado
A12: 9 | B12: 45580 | C12: 53.332.075-9 | D12: {=IFERROR( INDEX(R_CLIENTES!B:B, MATCH(C12, R_CLIENTES!A:A, 0) ), "" )} -> Condominio Jardin Central | E12: {=IFERROR( INDEX(R_CLIENTES!G:G, MATCH(C12, R_CLIENTES!A:A, 0) ), "" )} -> Vanessa Guerra | F12: no | G12: {=IFERROR( INDEX(R_CLIENTES!H:H, MATCH(C12, R_CLIENTES!A:A, 0) ), "" )} -> 9 49856345 | H12: Maximo Hudson | I12: Al finalizar | J12: 170000 | K12: =IF(J12="","",IF(F12="SI",J12*0.19,0)) -> 0 | L12: =IF(J12="","",J12+K12) -> 170000 | M12: Servicio Mantención | N12: Servicio incluye suministro, aceite de motor FAAC, Bisagras y accesorios. | O12: Rechazado
A13: 10 | B13: 45580 | C13: 50.000.000-0 | D13: {=IFERROR( INDEX(R_CLIENTES!B:B, MATCH(C13, R_CLIENTES!A:A, 0) ), "" )} -> Edificio Puerta Centro | E13: {=IFERROR( INDEX(R_CLIENTES!G:G, MATCH(C13, R_CLIENTES!A:A, 0) ), "" )} -> César | F13: no | G13: {=IFERROR( INDEX(R_CLIENTES!H:H, MATCH(C13, R_CLIENTES!A:A, 0) ), "" )} -> 9 98402129 | H13: Maximo Hudson | I13: Al finalizar | J13: 170000 | K13: =IF(J13="","",IF(F13="SI",J13*0.19,0)) -> 0 | L13: =IF(J13="","",J13+K13) -> 170000 | M13: Servicio Mantención | N13: Servicio incluye suministro, aceite de motor FAAC, Bisagras y accesorios. Modificación de portón incluye Quicios y perfil 100x50, incluye servicio de aplicación de pintura. | O13: Rechazado
A14: 11 | B14: 45580 | C14: 65.095.336-2 | D14: {=IFERROR( INDEX(R_CLIENTES!B:B, MATCH(C14, R_CLIENTES!A:A, 0) ), "" )} -> Condominio Neo Spazio | E14: {=IFERROR( INDEX(R_CLIENTES!G:G, MATCH(C14, R_CLIENTES!A:A, 0) ), "" )} -> Guillermo Negrete | F14: Si | G14: {=IFERROR( INDEX(R_CLIENTES!H:H, MATCH(C14, R_CLIENTES!A:A, 0) ), "" )} -> 9-93590543 | H14: Maximo Hudson | I14: 50 anticipo y 50 al finalizar | J14: 1250000 | K14: =IF(J14="","",IF(F14="SI",J14*0.19,0)) -> 237500 | L14: =IF(J14="","",J14+K14) -> 1487500 | M14: Central Citofonía Bticino | N14: Kit de citofono Btcino con expansor y fuente de alimentación con Instalacíon. | O14: Rechazado
A15: 12 | B15: 45509 | C15: 65216508-7 | D15: {=IFERROR( INDEX(R_CLIENTES!B:B, MATCH(C15, R_CLIENTES!A:A, 0) ), "" )} -> Condominio Mirador El Milagro | E15: {=IFERROR( INDEX(R_CLIENTES!G:G, MATCH(C15, R_CLIENTES!A:A, 0) ), "" )} -> Camila Godoy | F15: Si | G15: {=IFERROR( INDEX(R_CLIENTES!H:H, MATCH(C15, R_CLIENTES!A:A, 0) ), "" )} -> 9-44637185 | H15: Maximo Hudson | I15: 0 a 30 días | J15: 1435990 | K15: =IF(J15="","",IF(F15="SI",J15*0.19,0)) -> 272838.1 | L15: =IF(J15="","",J15+K15) -> 1708828.1 | M15: D10 STD Smart + 6mts cremallera + 1 Control 2b + 2 Bateria 12v + Baliza 24V + Fotocelda Smart Ina + con Inst Motor + Servicios Tecnico post venta | N15: Servicio incluye motor, instalación, accesorios y 2 controles. | O15: Aprobado
A16: 13 | B16: 45366 | C16: 53333086-k | D16: {=IFERROR( INDEX(R_CLIENTES!B:B, MATCH(C16, R_CLIENTES!A:A, 0) ), "" )} -> Condominio Colinas del Milagro | E16: {=IFERROR( INDEX(R_CLIENTES!G:G, MATCH(C16, R_CLIENTES!A:A, 0) ), "" )} -> Mauricio Araya | F16: Si | G16: {=IFERROR( INDEX(R_CLIENTES!H:H, MATCH(C16, R_CLIENTES!A:A, 0) ), "" )} -> 9-97269955 | H16: Maximo Hudson | I16: 0 a 30 días | J16: 1340000 | K16: =IF(J16="","",IF(F16="SI",J16*0.19,0)) -> 254600 | L16: =IF(J16="","",J16+K16) -> 1594600 | M16: Kit D10 T Smart + Fotocelda Smart + Inst Motor | N16: Servicio incluye motor, instalación, accesorios y 2 controles. | O16: Aprobado
A17: 14 | B17: 45586 | C17: 53333086-k | D17: {=IFERROR( INDEX(R_CLIENTES!B:B, MATCH(C17, R_CLIENTES!A:A, 0) ), "" )} -> Condominio Colinas del Milagro | E17: {=IFERROR( INDEX(R_CLIENTES!G:G, MATCH(C17, R_CLIENTES!A:A, 0) ), "" )} -> Mauricio Araya | F17: Si | G17: {=IFERROR( INDEX(R_CLIENTES!H:H, MATCH(C17, R_CLIENTES!A:A, 0) ), "" )} -> 9-97269955 | H17: Maximo Hudson | I17: 0 a 30 días | J17: 370000 | K17: =IF(J17="","",IF(F17="SI",J17*0.19,0)) -> 70300 | L17: =IF(J17="","",J17+K17) -> 440300 | M17: Instalación de chapa eléctrica Poli para exteriores. | N17: Servicio incluye chapa electromagnetica, cableado y garantía | O17: Aprobado
... A21: 18 | B21: 45615 | C21: 76.179.872-3 | D21: {=IFERROR( INDEX(R_CLIENTES!B:B, MATCH(C21, R_CLIENTES!A:A, 0) ), "" )} -> Sociedad Educacional Basaldiaz S.A | E21: {=IFERROR( INDEX(R_CLIENTES!G:G, MATCH(C21, R_CLIENTES!A:A, 0) ), "" )} -> Jonatan Mena | F21: Si | G21: {=IFERROR( INDEX(R_CLIENTES!H:H, MATCH(C21, R_CLIENTES!A:A, 0) ), "" )} -> 949911870 | H21: Maximo Hudson | I21: 50 anticipo y 50 al finalizar | J21: 1300000 | K21: =IF(J21="","",IF(F21="SI",J21*0.19,0)) -> 247000 | L21: =IF(J21="","",J21+K21) -> 1547000 | M21: Instalación de motor Centurion D10 con 6 cremalleras, baliza, fotoceldas, sistema WIFI de apertura remota, mano de obra y configuración. | N21: Servicio incluye motor, instalación, accesorios y 2 controles. | O21: Rechazado
A22: 19 | B22: 45622 | C22: 53332414-2 | D22: {=IFERROR( INDEX(R_CLIENTES!B:B, MATCH(C22, R_CLIENTES!A:A, 0) ), "" )} -> Portal del Valle II | E22: {=IFERROR( INDEX(R_CLIENTES!G:G, MATCH(C22, R_CLIENTES!A:A, 0) ), "" )} -> Mauricio Araya | F22: Si | G22: {=IFERROR( INDEX(R_CLIENTES!H:H, MATCH(C22, R_CLIENTES!A:A, 0) ), "" )} -> 9-97269955 | H22: Maximo Hudson | I22: 50 anticipo y 50 al finalizar | J22: 1645813 | K22: =IF(J22="","",IF(F22="SI",J22*0.19,0)) -> 312704.47 | L22: =IF(J22="","",J22+K22) -> 1958517.5 | M22: Instalación de motor Centurion D10Turbo con 6 cremalleras, baliza, fotoceldas, cambio de ruedas, Polines de Guías, mano de obra y configuración. | O22: Aprobado
A23: 20 | B23: 45699 | C23: 56047780-5 | D23: {=IFERROR( INDEX(R_CLIENTES!B:B, MATCH(C23, R_CLIENTES!A:A, 0) ), "" )} -> Comunidad Edificio Florencia | E23: {=IFERROR( INDEX(R_CLIENTES!G:G, MATCH(C23, R_CLIENTES!A:A, 0) ), "" )} -> Guillermo Negrete | F23: no | G23: {=IFERROR( INDEX(R_CLIENTES!H:H, MATCH(C23, R_CLIENTES!A:A, 0) ), "" )} -> 9-93590543 | H23: Maximo Hudson | I23: Al finalizar | J23: 140000 | K23: =IF(J23="","",IF(F23="SI",J23*0.19,0)) -> 0 | L23: =IF(J23="","",J23+K23) -> 140000 | M23: Reparación sensores Centurion D10 | O23: Aprobado
A24: 21 | B24: 45699 | C24: 65198585-4 | D24: {=IFERROR( INDEX(R_CLIENTES!B:B, MATCH(C24, R_CLIENTES!A:A, 0) ), "" )} -> Condominio Vicenza II | E24: {=IFERROR( INDEX(R_CLIENTES!G:G, MATCH(C24, R_CLIENTES!A:A, 0) ), "" )} -> Mauricio Araya | F24: Si | G24: {=IFERROR( INDEX(R_CLIENTES!H:H, MATCH(C24, R_CLIENTES!A:A, 0) ), "" )} -> 9-97269955 | H24: Maximo Hudson | I24: Al finalizar | J24: 670000 | K24: =IF(J24="","",IF(F24="SI",J24*0.19,0)) -> 127300 | L24: =IF(J24="","",J24+K24) -> 797300 | M24: Cambio de ruedas, Guías, cambio de cremalleras, enderezamiento de portón, y preparación para instalar motor | N24: Servicio sin equipo, solo materiales y accesorios | O24: Aprobado
A25: 22 | B25: 45699 | C25: 65198585-4 | D25: {=IFERROR( INDEX(R_CLIENTES!B:B, MATCH(C25, R_CLIENTES!A:A, 0) ), "" )} -> Condominio Vicenza II | E25: {=IFERROR( INDEX(R_CLIENTES!G:G, MATCH(C25, R_CLIENTES!A:A, 0) ), "" )} -> Mauricio Araya | F25: Si | G25: {=IFERROR( INDEX(R_CLIENTES!H:H, MATCH(C25, R_CLIENTES!A:A, 0) ), "" )} -> 9-97269955 | H25: Maximo Hudson | I25: Al finalizar | J25: 1000000 | K25: =IF(J25="","",IF(F25="SI",J25*0.19,0)) -> 190000 | L25: =IF(J25="","",J25+K25) -> 1190000 | M25: Centurion D10 Turbo Smart incluye instalación de 6 mts de cremallera y 2 controles remoto | N25: Motor D10 Turbo incluye cremalleras, controles y mano de obra | O25: Aprobado
A26: 23 | B26: 45699 | C26: 65198585-4 | D26: {=IFERROR( INDEX(R_CLIENTES!B:B, MATCH(C26, R_CLIENTES!A:A, 0) ), "" )} -> Condominio Vicenza II | E26: {=IFERROR( INDEX(R_CLIENTES!G:G, MATCH(C26, R_CLIENTES!A:A, 0) ), "" )} -> Mauricio Araya | F26: Si | G26: {=IFERROR( INDEX(R_CLIENTES!H:H, MATCH(C26, R_CLIENTES!A:A, 0) ), "" )} -> 9-97269955 | H26: Maximo Hudson | I26: Al finalizar | J26: 200000 | K26: =IF(J26="","",IF(F26="SI",J26*0.19,0)) -> 38000 | L26: =IF(J26="","",J26+K26) -> 238000 | M26: Reparación Portón por colisión | O26: Aprobado
A27: 24 | B27: 45856 | C27: 76866075-1 | D27: {=IFERROR( INDEX(R_CLIENTES!B:B, MATCH(C27, R_CLIENTES!A:A, 0) ), "" )} -> Paseo San Carlos VII | E27: {=IFERROR( INDEX(R_CLIENTES!G:G, MATCH(C27, R_CLIENTES!A:A, 0) ), "" )} -> Claudio García | F27: Si | G27: {=IFERROR( INDEX(R_CLIENTES!H:H, MATCH(C27, R_CLIENTES!A:A, 0) ), "" )} -> 9-84398698 | H27: Maximo Hudson | I27: Al finalizar | J27: 1600000 | K27: =IF(J27="","",IF(F27="SI",J27*0.19,0)) -> 304000 | L27: =IF(J27="","",J27+K27) -> 1904000 | M27: Instalación de motor Centurion D10Turbo con 6 cremalleras, baliza, fotoceldas, cambio de ruedas, Polines de Guías, mano de obra y configuración. | N27: Motor D10 Turbo incluye cremalleras, controles y mano de obra | O27: Aprobado
A28: 25 | B28: 45860 | C28: 65203446-2 | D28: {=IFERROR( INDEX(R_CLIENTES!B:B, MATCH(C28, R_CLIENTES!A:A, 0) ), "" )} -> Condominio Altos del Parque | E28: {=IFERROR( INDEX(R_CLIENTES!G:G, MATCH(C28, R_CLIENTES!A:A, 0) ), "" )} -> Maria Antoniera del Pino | F28: Si | G28: {=IFERROR( INDEX(R_CLIENTES!H:H, MATCH(C28, R_CLIENTES!A:A, 0) ), "" )} -> 9-84398698 | H28: Maximo Hudson | I28: Al finalizar | J28: 1310833 | K28: =IF(J28="","",IF(F28="SI",J28*0.19,0)) -> 249058.27 | L28: =IF(J28="","",J28+K28) -> 1559891.3 | M28: Instalación de motor Centurion D10Turbo con 6 cremalleras, baliza, fotoceldas, cambio de ruedas, Polines de Guías, mano de obra y configuración. | N28: Motor D10 Turbo incluye cremalleras, controles y mano de obra | O28: Aprobado
A29: 26 | B29: 45888 | C29: 65.229.898-2 | D29: {=IFERROR( INDEX(R_CLIENTES!B:B, MATCH(C29, R_CLIENTES!A:A, 0) ), "" )} -> Distrito Verde I | E29: {=IFERROR( INDEX(R_CLIENTES!G:G, MATCH(C29, R_CLIENTES!A:A, 0) ), "" )} -> Maria Antonieta del Pino | F29: Si | G29: {=IFERROR( INDEX(R_CLIENTES!H:H, MATCH(C29, R_CLIENTES!A:A, 0) ), "" )} -> 9-84398698 | H29: Maximo Hudson | I29: Al finalizar | J29: 545000 | K29: =IF(J29="","",IF(F29="SI",J29*0.19,0)) -> 103550 | L29: =IF(J29="","",J29+K29) -> 648550 | M29: Recuperación automatización portón Distrito verde 1 (incluye foto celdas internas inalambricas) | N29: Dtto Verde 1 Reparación por concepto defectos de instalacion de cremalleras, instalación perfil en medio de recorrido , puesta en marcha y configuración de equipo | O29: Aprobado
A30: 27 | B30: 45888 | C30: 65.244.656- 6 | D30: {=IFERROR( INDEX(R_CLIENTES!B:B, MATCH(C30, R_CLIENTES!A:A, 0) ), "" )} -> Distrito Verde II | E30: {=IFERROR( INDEX(R_CLIENTES!G:G, MATCH(C30, R_CLIENTES!A:A, 0) ), "" )} -> Maria Antonieta del Pino | F30: Si | G30: {=IFERROR( INDEX(R_CLIENTES!H:H, MATCH(C30, R_CLIENTES!A:A, 0) ), "" )} -> 9-84398698 | H30: Maximo Hudson | I30: Al finalizar | J30: 840000 | K30: =IF(J30="","",IF(F30="SI",J30*0.19,0)) -> 159600 | L30: =IF(J30="","",J30+K30) -> 999600 | M30: Recuperación automatización portón Distrito verde 1 (incluye foto celdas internas inalambricas) | N30: Dtto Verde 2 Reparación por concepto defectos de instalacion de cremalleras, instalación perfil en medio de recorrido , puesta en marcha y configuración de equipo | O30: Aprobado
A31: 28 | B31: 45911 | C31: 79866075-1 | D31: {=IFERROR( INDEX(R_CLIENTES!B:B, MATCH(C31, R_CLIENTES!A:A, 0) ), "" )} -> Cond Doña Anita | E31: {=IFERROR( INDEX(R_CLIENTES!G:G, MATCH(C31, R_CLIENTES!A:A, 0) ), "" )} -> Noema Reyes | F31: no | G31: {=IFERROR( INDEX(R_CLIENTES!H:H, MATCH(C31, R_CLIENTES!A:A, 0) ), "" )} -> 9 7731 14628 | H31: Maximo Hudson | I31: 50 anticipo y 50 al finalizar | J31: 3950000 | K31: =IF(J31="","",IF(F31="SI",J31*0.19,0)) -> 0 | L31: =IF(J31="","",J31+K31) -> 3950000 | M31: Reconfiguración e instalación de moptor D10 Turbo | N31: Mano de obra de reconfiguracion motor batiente a corredizo, trabajos de obra civil e instalación de motor D10 Turbo con kit de instalacion. | O31: Rechazado
A32: 29 | B32: 45916 | C32: 53320939-4 | D32: {=IFERROR( INDEX(R_CLIENTES!B:B, MATCH(C32, R_CLIENTES!A:A, 0) ), "" )} -> Condominio Paseo Peñuelas | E32: {=IFERROR( INDEX(R_CLIENTES!G:G, MATCH(C32, R_CLIENTES!A:A, 0) ), "" )} -> Adm Victor Figueroa | F32: Si | G32: {=IFERROR( INDEX(R_CLIENTES!H:H, MATCH(C32, R_CLIENTES!A:A, 0) ), "" )} -> 9-59823214 | H32: Maximo Hudson | I32: Al finalizar | J32: 1180000 | K32: =IF(J32="","",IF(F32="SI",J32*0.19,0)) -> 224200 | L32: =IF(J32="","",J32+K32) -> 1404200 | M32: D10 STD Smart + 6mts cremallera + 2 Control 2b + 2 Bateria 12v + Fotocelda Smart Ina Serial: ZAXZ200031C2 | N32: Serial Motor: ZAXZ200031C2 | O32: Aprobado
A33: 29 | B33: 45916 | C33: 53320939-4 | D33: {=IFERROR( INDEX(R_CLIENTES!B:B, MATCH(C33, R_CLIENTES!A:A, 0) ), "" )} -> Condominio Paseo Peñuelas | E33: {=IFERROR( INDEX(R_CLIENTES!G:G, MATCH(C33, R_CLIENTES!A:A, 0) ), "" )} -> Adm Victor Figueroa | F33: no | G33: {=IFERROR( INDEX(R_CLIENTES!H:H, MATCH(C33, R_CLIENTES!A:A, 0) ), "" )} -> 9-59823214 | H33: Maximo Hudson | I33: Al finalizar | J33: 370000 | K33: =IF(J33="","",IF(F33="SI",J33*0.19,0)) -> 0 | L33: =IF(J33="","",J33+K33) -> 370000 | M33: Con Inst Motor + Servicios Tecnico post vent | N33: Solo servicio y mano de obra | O33: Aprobado
A34: 30 | B34: 45916 | C34: 53320939-4 | D34: {=IFERROR( INDEX(R_CLIENTES!B:B, MATCH(C34, R_CLIENTES!A:A, 0) ), "" )} -> Condominio Paseo Peñuelas | E34: {=IFERROR( INDEX(R_CLIENTES!G:G, MATCH(C34, R_CLIENTES!A:A, 0) ), "" )} -> Adm Victor Figueroa | F34: no | G34: {=IFERROR( INDEX(R_CLIENTES!H:H, MATCH(C34, R_CLIENTES!A:A, 0) ), "" )} -> 9-59823214 | H34: Maximo Hudson | I34: Al finalizar | J34: 200000 | K34: =IF(J34="","",IF(F34="SI",J34*0.19,0)) -> 0 | L34: =IF(J34="","",J34+K34) -> 200000 | M34: Manteción programada 2025 | N34: Mantención programada 2025 | O34: Aprobado
A35: 31 | B35: 45883 | C35: 65216508-7 | D35: {=IFERROR( INDEX(R_CLIENTES!B:B, MATCH(C35, R_CLIENTES!A:A, 0) ), "" )} -> Condominio Mirador El Milagro | E35: {=IFERROR( INDEX(R_CLIENTES!G:G, MATCH(C35, R_CLIENTES!A:A, 0) ), "" )} -> Camila Godoy | F35: Si | G35: {=IFERROR( INDEX(R_CLIENTES!H:H, MATCH(C35, R_CLIENTES!A:A, 0) ), "" )} -> 9-44637185 | H35: Maximo Hudson | I35: Al finalizar | J35: 200000 | K35: =IF(J35="","",IF(F35="SI",J35*0.19,0)) -> 38000 | L35: =IF(J35="","",J35+K35) -> 238000 | M35: Manteción programada 2025 | N35: Mantención programada 2025 | O35: Aprobado
A36: 32 | B36: 45938 | C36: 65216508-7 | D36: {=IFERROR( INDEX(R_CLIENTES!B:B, MATCH(C36, R_CLIENTES!A:A, 0) ), "" )} -> Condominio Mirador El Milagro | E36: {=IFERROR( INDEX(R_CLIENTES!G:G, MATCH(C36, R_CLIENTES!A:A, 0) ), "" )} -> Camila Godoy | F36: no | G36: {=IFERROR( INDEX(R_CLIENTES!H:H, MATCH(C36, R_CLIENTES!A:A, 0) ), "" )} -> 9-44637185 | H36: Maximo Hudson | I36: Al finalizar | J36: 153000 | K36: =IF(J36="","",IF(F36="SI",J36*0.19,0)) -> 0 | L36: =IF(J36="","",J36+K36) -> 153000 | M36: Controles Centurion | N36: 9 controles NOVA 2CH | O36: Aprobado
A37: 33 | B37: 45883 | C37: 53333086-k | D37: {=IFERROR( INDEX(R_CLIENTES!B:B, MATCH(C37, R_CLIENTES!A:A, 0) ), "" )} -> Condominio Colinas del Milagro | E37: {=IFERROR( INDEX(R_CLIENTES!G:G, MATCH(C37, R_CLIENTES!A:A, 0) ), "" )} -> Mauricio Araya | F37: Si | G37: {=IFERROR( INDEX(R_CLIENTES!H:H, MATCH(C37, R_CLIENTES!A:A, 0) ), "" )} -> 9-97269955 | H37: Maximo Hudson | I37: Al finalizar | J37: 200000 | K37: =IF(J37="","",IF(F37="SI",J37*0.19,0)) -> 38000 | L37: =IF(J37="","",J37+K37) -> 238000 | M37: Manteción programada 2025 | N37: Manteción programada 2025 | O37: Aprobado
A38: 34 | B38: 45883 | C38: 65198585-4 | D38: {=IFERROR( INDEX(R_CLIENTES!B:B, MATCH(C38, R_CLIENTES!A:A, 0) ), "" )} -> Condominio Vicenza II | E38: {=IFERROR( INDEX(R_CLIENTES!G:G, MATCH(C38, R_CLIENTES!A:A, 0) ), "" )} -> Mauricio Araya | F38: Si | G38: {=IFERROR( INDEX(R_CLIENTES!H:H, MATCH(C38, R_CLIENTES!A:A, 0) ), "" )} -> 9-97269955 | H38: Maximo Hudson | I38: Al finalizar | J38: 200000 | K38: =IF(J38="","",IF(F38="SI",J38*0.19,0)) -> 38000 | L38: =IF(J38="","",J38+K38) -> 238000 | M38: Manteción programada 2025 | N38: Manteción programada 2025 | O38: Aprobado
... A40: 36 | B40: 45938 | C40: 53332414-2 | D40: {=IFERROR( INDEX(R_CLIENTES!B:B, MATCH(C40, R_CLIENTES!A:A, 0) ), "" )} -> Portal del Valle II | E40: {=IFERROR( INDEX(R_CLIENTES!G:G, MATCH(C40, R_CLIENTES!A:A, 0) ), "" )} -> Mauricio Araya | F40: Si | G40: {=IFERROR( INDEX(R_CLIENTES!H:H, MATCH(C40, R_CLIENTES!A:A, 0) ), "" )} -> 9-97269955 | H40: Maximo Hudson | I40: Al finalizar | J40: 290000 | K40: =IF(J40="","",IF(F40="SI",J40*0.19,0)) -> 55100 | L40: =IF(J40="","",J40+K40) -> 345100 | M40: Servicio de perfil de apoyo 100x100 con 3ra rueda de aguante para estabilizacion de paño | N40: Estabilizacion y separación de paño portón de pared vecinal. | O40: Aprobado
A41: 37 | B41: 45950 | C41: 90000000-1 | D41: {=IFERROR( INDEX(R_CLIENTES!B:B, MATCH(C41, R_CLIENTES!A:A, 0) ), "" )} -> Condominio Gabriela Mistral | E41: {=IFERROR( INDEX(R_CLIENTES!G:G, MATCH(C41, R_CLIENTES!A:A, 0) ), "" )} -> Mauricio Araya | F41: no | G41: {=IFERROR( INDEX(R_CLIENTES!H:H, MATCH(C41, R_CLIENTES!A:A, 0) ), "" )} -> 9-97269955 | H41: Maximo Hudson | I41: Al finalizar | J41: 250000 | K41: =IF(J41="","",IF(F41="SI",J41*0.19,0)) -> 0 | L41: =IF(J41="","",J41+K41) -> 250000 | M41: Chapa ODIS Model 783 Instalada | O41: Aprobado
A42: 38 | B42: 45950 | C42: 53332351-0 | D42: {=IFERROR( INDEX(R_CLIENTES!B:B, MATCH(C42, R_CLIENTES!A:A, 0) ), "" )} -> Cond Aires de La Florida 4 | E42: {=IFERROR( INDEX(R_CLIENTES!G:G, MATCH(C42, R_CLIENTES!A:A, 0) ), "" )} -> Camila Godoy | F42: Si | G42: {=IFERROR( INDEX(R_CLIENTES!H:H, MATCH(C42, R_CLIENTES!A:A, 0) ), "" )} -> 9-7684 0230 | H42: Maximo Hudson | I42: 50 anticipo y 50 al finalizar | J42: 2000000 | K42: =IF(J42="","",IF(F42="SI",J42*0.19,0)) -> 380000 | L42: =IF(J42="","",J42+K42) -> 2380000 | M42: Kit D10 Smart con 6mts Cremallera M, CR, Baliza y fotocelda Smart | N42: Instalación de motor Centurion D10 Turbo, cambio de ruedas, cambio de guías y acondicionamiento de base de motor. | O42: Pendiente
A43: 39 | B43: 45972 | C43: 56047780-5 | D43: {=IFERROR( INDEX(R_CLIENTES!B:B, MATCH(C43, R_CLIENTES!A:A, 0) ), "" )} -> Comunidad Edificio Florencia | E43: {=IFERROR( INDEX(R_CLIENTES!G:G, MATCH(C43, R_CLIENTES!A:A, 0) ), "" )} -> Guillermo Negrete | F43: no | G43: {=IFERROR( INDEX(R_CLIENTES!H:H, MATCH(C43, R_CLIENTES!A:A, 0) ), "" )} -> 9-93590543 | H43: Maximo Hudson | I43: Al finalizar | J43: 430000 | K43: =IF(J43="","",IF(F43="SI",J43*0.19,0)) -> 0 | L43: =IF(J43="","",J43+K43) -> 430000 | M43: Recuperación de 8 cámaras IP y recuperación señal Protegus 2 | N43: Recuperación de 8 cámaras IP y recuperación señal Protegus 2 | O43: Aprobado
A44: 40 | B44: 45975 | C44: 90000002-1 | D44: {=IFERROR( INDEX(R_CLIENTES!B:B, MATCH(C44, R_CLIENTES!A:A, 0) ), "" )} -> Condominio Golf III | E44: {=IFERROR( INDEX(R_CLIENTES!G:G, MATCH(C44, R_CLIENTES!A:A, 0) ), "" )} -> Oscar Castro | F44: Si | G44: {=IFERROR( INDEX(R_CLIENTES!H:H, MATCH(C44, R_CLIENTES!A:A, 0) ), "" )} -> 9 9450 8233 | H44: Maximo Hudson | I44: 50 anticipo y 50 al finalizar | J44: 8250000 | K44: =IF(J44="","",IF(F44="SI",J44*0.19,0)) -> 1567500 | L44: =IF(J44="","",J44+K44) -> 9817500 | M44: Servicio de venta e instalación 17 cámaras IP en la perfiferia del Condominio con alcance de antenas inalámbricas. | N44: Servicio de instalación y puesta en marcha de circuito CCTV IP implementando antenas inalámbricas. | O44: Pendiente
A45: 41 | B45: 45979 | C45: 76470822-9 | D45: {=IFERROR( INDEX(R_CLIENTES!B:B, MATCH(C45, R_CLIENTES!A:A, 0) ), "" )} -> Sociedad Educacional Shalom SpA | E45: {=IFERROR( INDEX(R_CLIENTES!G:G, MATCH(C45, R_CLIENTES!A:A, 0) ), "" )} -> Jorge Adm | F45: Si | G45: {=IFERROR( INDEX(R_CLIENTES!H:H, MATCH(C45, R_CLIENTES!A:A, 0) ), "" )} -> 999847687 | H45: Maximo Hudson | I45: Al finalizar | J45: 200000 | K45: =IF(J45="","",IF(F45="SI",J45*0.19,0)) -> 38000 | L45: =IF(J45="","",J45+K45) -> 238000 | M45: Servicio de mantención Programada 2025 | N45: Servicio de mantención Programada 2025 | O45: Pendiente
A46: 42 | B46: 45979 | C46: 65216508-7 | D46: {=IFERROR( INDEX(R_CLIENTES!B:B, MATCH(C46, R_CLIENTES!A:A, 0) ), "" )} -> Condominio Mirador El Milagro | E46: {=IFERROR( INDEX(R_CLIENTES!G:G, MATCH(C46, R_CLIENTES!A:A, 0) ), "" )} -> Camila Godoy | F46: no | G46: {=IFERROR( INDEX(R_CLIENTES!H:H, MATCH(C46, R_CLIENTES!A:A, 0) ), "" )} -> 9-44637185 | H46: Maximo Hudson | I46: Al finalizar | J46: 136000 | K46: =IF(J46="","",IF(F46="SI",J46*0.19,0)) -> 0 | L46: =IF(J46="","",J46+K46) -> 136000 | M46: Venta de 8 controles NOVA 2CH | N46: Venta de 8 controles NOVA 2CH | O46: Aprobado
...

Sheet Detalle Cotización
A1: Detalle de cotizaciones
A3: Columna 1 | B3: Nro Cot | C3: Nro de fila | D3: Cliente | E3: RUT | F3: IVA | G3: Proveedor | H3: Cod | I3: Producto / Servicio | J3: Cant | K3: Valor unitario | L3: Descuento | M3: Sub- Total unitario | N3: VALOR IVA | O3: Total Uni | P3: Total acumulado | Q3: Margen Unitario | R3: Margen acumulado | S3: Columna 2
A4: =B4&"-"&C4 -> 1-1 | B4: =IF(R_COTIZACIONES!A4="","",R_COTIZACIONES!A4) -> 1 | C4: =IF(B4="","",COUNTIF($B$4:B4,B4)) -> 1 | D4: {=IF(B4="","",IFERROR( INDEX(R_COTIZACIONES!D:D,MATCH(B4,R_COTIZACIONES!A:A,0)), ""))} -> Condominio Mirador Los Clarines | E4: {=IF(B4="","",IFERROR( INDEX(R_COTIZACIONES!C:C,MATCH(B4,R_COTIZACIONES!A:A,0)), ""))} -> 53334332-5 | F4: Si | G4: Particular | H4: S07 | I4: =IF(H4="","",VLOOKUP(H4,'Base de datos'!$E:$G,3,FALSE)) -> Mantención programada | J4: 1 | K4: =IF(H4="","",VLOOKUP(H4,'Base de datos'!E:N,10,FALSE)) -> 200000 | L4: 0 | M4: =IF(K4="","",J4*K4*(1-IFERROR(L4,0))) -> 200000 | N4: =IF(M4="","",IF(F4="SI",M4*0.19,0)) -> 38000 | O4: =IF(K4="","",M4+N4) -> 238000 | P4: =IF(K4="","",SUMIF($B:$B,B4,$O:$O)) -> 238000 | Q4: =IF(H4="","",VLOOKUP(H4,'Base de datos'!E:M,9,FALSE)) -> 100000 | R4: =IF(Q4="","",SUMIF($B:$B,B4,$Q:$Q)) -> 100000
A5: =B5&"-"&C5 -> 2-1 | B5: 2 | C5: =IF(B5="","",COUNTIF($B$4:B5,B5)) -> 1 | D5: {=IF(B5="","",IFERROR( INDEX(R_COTIZACIONES!D:D,MATCH(B5,R_COTIZACIONES!A:A,0)), ""))} -> Condominio Colinas del Milagro | E5: {=IF(B5="","",IFERROR( INDEX(R_COTIZACIONES!C:C,MATCH(B5,R_COTIZACIONES!A:A,0)), ""))} -> 53333086-k | F5: Si | G5: Particular | H5: S07 | I5: =IF(H5="","",VLOOKUP(H5,'Base de datos'!$E:$G,3,FALSE)) -> Mantención programada | J5: 1 | K5: =IF(H5="","",VLOOKUP(H5,'Base de datos'!E:N,10,FALSE)) -> 200000 | L5: 0 | M5: =IF(K5="","",J5*K5*(1-IFERROR(L5,0))) -> 200000 | N5: =IF(M5="","",IF(F5="SI",M5*0.19,0)) -> 38000 | O5: =IF(K5="","",M5+N5) -> 238000 | P5: =IF(K5="","",SUMIF($B:$B,B5,$O:$O)) -> 238000 | Q5: =IF(H5="","",VLOOKUP(H5,'Base de datos'!E:M,9,FALSE)) -> 100000 | R5: =IF(Q5="","",SUMIF($B:$B,B5,$Q:$Q)) -> 100000
A6: =B6&"-"&C6 -> 3-1 | B6: 3 | C6: =IF(B6="","",COUNTIF($B$4:B6,B6)) -> 1 | D6: {=IF(B6="","",IFERROR( INDEX(R_COTIZACIONES!D:D,MATCH(B6,R_COTIZACIONES!A:A,0)), ""))} -> Comunidad Edificio Florencia | E6: {=IF(B6="","",IFERROR( INDEX(R_COTIZACIONES!C:C,MATCH(B6,R_COTIZACIONES!A:A,0)), ""))} -> 56047780-5 | F6: Si | G6: RW | H6: WP17 | I6: =IF(H6="","",VLOOKUP(H6,'Base de datos'!$E:$G,3,FALSE)) -> Controlador Wifi WP17 | J6: 1 | K6: 220000 | L6: 0 | M6: =IF(K6="","",J6*K6*(1-IFERROR(L6,0))) -> 220000 | N6: =IF(M6="","",IF(F6="SI",M6*0.19,0)) -> 41800 | O6: =IF(K6="","",M6+N6) -> 261800 | P6: =IF(K6="","",SUMIF($B:$B,B6,$O:$O)) -> 261800 | Q6: =IF(H6="","",VLOOKUP(H6,'Base de datos'!E:M,9,FALSE)) -> 161840 | R6: =IF(Q6="","",SUMIF($B:$B,B6,$Q:$Q)) -> 161840
A7: =B7&"-"&C7 -> 4-1 | B7: 4 | C7: =IF(B7="","",COUNTIF($B$4:B7,B7)) -> 1 | D7: {=IF(B7="","",IFERROR( INDEX(R_COTIZACIONES!D:D,MATCH(B7,R_COTIZACIONES!A:A,0)), ""))} -> CONDOMINIO V.I.V.E LA FLORIDA ORIENTE | E7: {=IF(B7="","",IFERROR( INDEX(R_COTIZACIONES!C:C,MATCH(B7,R_COTIZACIONES!A:A,0)), ""))} -> 53322672-8 | F7: Si | G7: Particular | H7: S03 | I7: =IF(H7="","",VLOOKUP(H7,'Base de datos'!$E:$G,3,FALSE)) -> Instalación de ruedas (Unidad) | J7: 1 | K7: 200000 | L7: 0 | M7: =IF(K7="","",J7*K7*(1-IFERROR(L7,0))) -> 200000 | N7: =IF(M7="","",IF(F7="SI",M7*0.19,0)) -> 38000 | O7: =IF(K7="","",M7+N7) -> 238000 | P7: =IF(K7="","",SUMIF($B:$B,B7,$O:$O)) -> 357000 | Q7: =IF(H7="","",VLOOKUP(H7,'Base de datos'!E:M,9,FALSE)) -> 22500 | R7: =IF(Q7="","",SUMIF($B:$B,B7,$Q:$Q)) -> 45000
A8: =B8&"-"&C8 -> 4-2 | B8: 4 | C8: =IF(B8="","",COUNTIF($B$4:B8,B8)) -> 2 | D8: {=IF(B8="","",IFERROR( INDEX(R_COTIZACIONES!D:D,MATCH(B8,R_COTIZACIONES!A:A,0)), ""))} -> CONDOMINIO V.I.V.E LA FLORIDA ORIENTE | E8: {=IF(B8="","",IFERROR( INDEX(R_COTIZACIONES!C:C,MATCH(B8,R_COTIZACIONES!A:A,0)), ""))} -> 53322672-8 | F8: Si | G8: Particular | H8: S03 | I8: =IF(H8="","",VLOOKUP(H8,'Base de datos'!$E:$G,3,FALSE)) -> Instalación de ruedas (Unidad) | J8: 1 | K8: 100000 | L8: 0 | M8: =IF(K8="","",J8*K8*(1-IFERROR(L8,0))) -> 100000 | N8: =IF(M8="","",IF(F8="SI",M8*0.19,0)) -> 19000 | O8: =IF(K8="","",M8+N8) -> 119000 | P8: =IF(K8="","",SUMIF($B:$B,B8,$O:$O)) -> 357000 | Q8: =IF(H8="","",VLOOKUP(H8,'Base de datos'!E:M,9,FALSE)) -> 22500 | R8: =IF(Q8="","",SUMIF($B:$B,B8,$Q:$Q)) -> 45000
A9: =B9&"-"&C9 -> 5-1 | B9: 5 | C9: =IF(B9="","",COUNTIF($B$4:B9,B9)) -> 1 | D9: {=IF(B9="","",IFERROR( INDEX(R_COTIZACIONES!D:D,MATCH(B9,R_COTIZACIONES!A:A,0)), ""))} -> Condominio Lomas de San Joaquin | E9: {=IF(B9="","",IFERROR( INDEX(R_COTIZACIONES!C:C,MATCH(B9,R_COTIZACIONES!A:A,0)), ""))} -> 50.000.001-0 | F9: Si | G9: APACOM | H9: D10TKIT | I9: =IF(H9="","",VLOOKUP(H9,'Base de datos'!$E:$G,3,FALSE)) -> D10 Turbo (6 crem y 2 controles) | J9: 1 | K9: 1400000 | L9: 0 | M9: =IF(K9="","",J9*K9*(1-IFERROR(L9,0))) -> 1400000 | N9: =IF(M9="","",IF(F9="SI",M9*0.19,0)) -> 266000 | O9: =IF(K9="","",M9+N9) -> 1666000 | P9: =IF(K9="","",SUMIF($B:$B,B9,$O:$O)) -> 1666000 | Q9: =IF(H9="","",VLOOKUP(H9,'Base de datos'!E:M,9,FALSE)) -> 450483.6 | R9: =IF(Q9="","",SUMIF($B:$B,B9,$Q:$Q)) -> 450483.6
A10: =B10&"-"&C10 -> 6-1 | B10: 6 | C10: =IF(B10="","",COUNTIF($B$4:B10,B10)) -> 1 | D10: {=IF(B10="","",IFERROR( INDEX(R_COTIZACIONES!D:D,MATCH(B10,R_COTIZACIONES!A:A,0)), ""))} -> Comunidad Edificio Florencia | E10: {=IF(B10="","",IFERROR( INDEX(R_COTIZACIONES!C:C,MATCH(B10,R_COTIZACIONES!A:A,0)), ""))} -> 56047780-5 | F10: Si | G10: Particular | H10: S07 | I10: =IF(H10="","",VLOOKUP(H10,'Base de datos'!$E:$G,3,FALSE)) -> Mantención programada | J10: 1 | K10: 230000 | L10: 0 | M10: =IF(K10="","",J10*K10*(1-IFERROR(L10,0))) -> 230000 | N10: =IF(M10="","",IF(F10="SI",M10*0.19,0)) -> 43700 | O10: =IF(K10="","",M10+N10) -> 273700 | P10: =IF(K10="","",SUMIF($B:$B,B10,$O:$O)) -> 273700 | Q10: =IF(H10="","",VLOOKUP(H10,'Base de datos'!E:M,9,FALSE)) -> 100000 | R10: =IF(Q10="","",SUMIF($B:$B,B10,$Q:$Q)) -> 100000
A11: =B11&"-"&C11 -> 7-1 | B11: 7 | C11: =IF(B11="","",COUNTIF($B$4:B11,B11)) -> 1 | D11: {=IF(B11="","",IFERROR( INDEX(R_COTIZACIONES!D:D,MATCH(B11,R_COTIZACIONES!A:A,0)), ""))} -> Condominio Los Tamarindos I | E11: {=IF(B11="","",IFERROR( INDEX(R_COTIZACIONES!C:C,MATCH(B11,R_COTIZACIONES!A:A,0)), ""))} -> 53.322.860-7 | F11: no | G11: RW | H11: D10SKIT | I11: =IF(H11="","",VLOOKUP(H11,'Base de datos'!$E:$G,3,FALSE)) -> D10 Standard Kit 1(6 crem y 2 controles) | J11: 1 | K11: 1500000 | L11: 0 | M11: =IF(K11="","",J11*K11*(1-IFERROR(L11,0))) -> 1500000 | N11: =IF(M11="","",IF(F11="SI",M11*0.19,0)) -> 0 | O11: =IF(K11="","",M11+N11) -> 1500000 | P11: =IF(K11="","",SUMIF($B:$B,B11,$O:$O)) -> 1500000 | Q11: =IF(H11="","",VLOOKUP(H11,'Base de datos'!E:M,9,FALSE)) -> 420000 | R11: =IF(Q11="","",SUMIF($B:$B,B11,$Q:$Q)) -> 420000
A12: =B12&"-"&C12 -> 8-1 | B12: 8 | C12: =IF(B12="","",COUNTIF($B$4:B12,B12)) -> 1 | D12: {=IF(B12="","",IFERROR( INDEX(R_COTIZACIONES!D:D,MATCH(B12,R_COTIZACIONES!A:A,0)), ""))} -> Condominio Los Tamarindos I | E12: {=IF(B12="","",IFERROR( INDEX(R_COTIZACIONES!C:C,MATCH(B12,R_COTIZACIONES!A:A,0)), ""))} -> 53.322.860-7 | F12: no | G12: RW | H12: WP17 | I12: =IF(H12="","",VLOOKUP(H12,'Base de datos'!$E:$G,3,FALSE)) -> Controlador Wifi WP17 | J12: 1 | K12: 220000 | L12: 0 | M12: =IF(K12="","",J12*K12*(1-IFERROR(L12,0))) -> 220000 | N12: =IF(M12="","",IF(F12="SI",M12*0.19,0)) -> 0 | O12: =IF(K12="","",M12+N12) -> 220000 | P12: =IF(K12="","",SUMIF($B:$B,B12,$O:$O)) -> 220000 | Q12: =IF(H12="","",VLOOKUP(H12,'Base de datos'!E:M,9,FALSE)) -> 161840 | R12: =IF(Q12="","",SUMIF($B:$B,B12,$Q:$Q)) -> 161840
A13: =B13&"-"&C13 -> 9-1 | B13: 9 | C13: =IF(B13="","",COUNTIF($B$4:B13,B13)) -> 1 | D13: {=IF(B13="","",IFERROR( INDEX(R_COTIZACIONES!D:D,MATCH(B13,R_COTIZACIONES!A:A,0)), ""))} -> Condominio Jardin Central | E13: {=IF(B13="","",IFERROR( INDEX(R_COTIZACIONES!C:C,MATCH(B13,R_COTIZACIONES!A:A,0)), ""))} -> 53.332.075-9 | F13: no | G13: Particular | H13: S07 | I13: =IF(H13="","",VLOOKUP(H13,'Base de datos'!$E:$G,3,FALSE)) -> Mantención programada | J13: 1 | K13: 170000 | L13: 0 | M13: =IF(K13="","",J13*K13*(1-IFERROR(L13,0))) -> 170000 | N13: =IF(M13="","",IF(F13="SI",M13*0.19,0)) -> 0 | O13: =IF(K13="","",M13+N13) -> 170000 | P13: =IF(K13="","",SUMIF($B:$B,B13,$O:$O)) -> 170000 | Q13: =IF(H13="","",VLOOKUP(H13,'Base de datos'!E:M,9,FALSE)) -> 100000 | R13: =IF(Q13="","",SUMIF($B:$B,B13,$Q:$Q)) -> 100000
A14: =B14&"-"&C14 -> 10-1 | B14: 10 | C14: =IF(B14="","",COUNTIF($B$4:B14,B14)) -> 1 | D14: {=IF(B14="","",IFERROR( INDEX(R_COTIZACIONES!D:D,MATCH(B14,R_COTIZACIONES!A:A,0)), ""))} -> Edificio Puerta Centro | E14: {=IF(B14="","",IFERROR( INDEX(R_COTIZACIONES!C:C,MATCH(B14,R_COTIZACIONES!A:A,0)), ""))} -> 50.000.000-0 | F14: no | G14: Particular | H14: S07 | I14: =IF(H14="","",VLOOKUP(H14,'Base de datos'!$E:$G,3,FALSE)) -> Mantención programada | J14: 1 | K14: 170000 | L14: 0 | M14: =IF(K14="","",J14*K14*(1-IFERROR(L14,0))) -> 170000 | N14: =IF(M14="","",IF(F14="SI",M14*0.19,0)) -> 0 | O14: =IF(K14="","",M14+N14) -> 170000 | P14: =IF(K14="","",SUMIF($B:$B,B14,$O:$O)) -> 170000 | Q14: =IF(H14="","",VLOOKUP(H14,'Base de datos'!E:M,9,FALSE)) -> 100000 | R14: =IF(Q14="","",SUMIF($B:$B,B14,$Q:$Q)) -> 100000
A15: =B15&"-"&C15 -> 11-1 | B15: 11 | C15: =IF(B15="","",COUNTIF($B$4:B15,B15)) -> 1 | D15: {=IF(B15="","",IFERROR( INDEX(R_COTIZACIONES!D:D,MATCH(B15,R_COTIZACIONES!A:A,0)), ""))} -> Condominio Neo Spazio | E15: {=IF(B15="","",IFERROR( INDEX(R_COTIZACIONES!C:C,MATCH(B15,R_COTIZACIONES!A:A,0)), ""))} -> 65.095.336-2 | F15: Si | G15: Otro | H15: S07 | I15: =IF(H15="","",VLOOKUP(H15,'Base de datos'!$E:$G,3,FALSE)) -> Mantención programada | J15: 1 | K15: 1250000 | L15: 0 | M15: =IF(K15="","",J15*K15*(1-IFERROR(L15,0))) -> 1250000 | N15: =IF(M15="","",IF(F15="SI",M15*0.19,0)) -> 237500 | O15: =IF(K15="","",M15+N15) -> 1487500 | P15: =IF(K15="","",SUMIF($B:$B,B15,$O:$O)) -> 1487500 | Q15: =IF(H15="","",VLOOKUP(H15,'Base de datos'!E:M,9,FALSE)) -> 100000 | R15: =IF(Q15="","",SUMIF($B:$B,B15,$Q:$Q)) -> 100000
